<?xml version="1.0" ?>
<!-- =================================================================================== -->
<!-- |    This document was autogenerated by xacro from /home/issaiass/ros2_slam_workshop/install/mobRobURDF_description/share/mobRobURDF_description/urdf/temp/4_wheeled/mobRob.xacro | -->
<!-- |    EDITING THIS FILE BY HAND IS NOT RECOMMENDED                                 | -->
<!-- =================================================================================== -->
<robot xmlns:xacro="http://www.ros.org/wiki/xacro" name="mobRob">


  <link name="base_footprint"/>
  <!-- Base Link -->
  <link name="base_link"/>

  <joint name="base_joint" type="fixed">
    <parent link="base_link"/>
    <child link="base_footprint"/>
  </joint>

  <!-- Materials -->
  <material name="Gray">
    <color rgba="0.5 0.5 0.5 1.0"/>
  </material>
  <material name="Black">
    <color rgba="0.0 0.0 0.0 1.0"/>
  </material>
  <material name="Red">
    <color rgba="1.0 0.0 0.0 1.0"/>
  </material>
  <material name="Blue">
    <color rgba="0.0 0.0 1.0 1.0"/>
  </material>
  <material name="Green">
    <color rgba="0.0 1.0 0.0 1.0"/>
  </material>
  <material name="White">
    <color rgba="1.0 1.0 1.0 1.0"/>
  </material>

  <!-- Chassis -->
  <link name="chassis">
    <inertial>
      <mass value="5.0"/>
      <origin rpy="0 0 0" xyz="0 0 0"/>
      <inertia ixx="0.3042" ixy="0.0" ixz="0.0" iyy="0.6375" iyz="0.0" izz="0.8667"/>
    </inertial>
    <visual>
      <origin rpy="0 0 0" xyz="0 0 0"/>
      <geometry>
        <box size="1.2 0.8 0.3"/>
      </geometry>
      <material name="Gray"/>
    </visual>
    <collision>
      <origin rpy="0 0 0" xyz="0 0 0"/>
      <geometry>
        <box size="1.2 0.8 0.3"/>
      </geometry>
    </collision>
  </link>

  <!-- Joint: Base Link and Chassis -->
  <joint name="base_to_chassis" type="fixed">
    <parent link="base_link"/>
    <child link="chassis"/>
    <!--origin rpy="0 0 0" xyz="0 0 0.15"/-->
    <origin rpy="0 0 0" xyz="0 0 0.05"/>    
  </joint>



  <!-- FRONT WHEELS -->

  <!-- Front Left Wheel -->
  <link name="front_left_wheel">
    <inertial>
      <mass value="0.7"/>  
      <origin rpy="1.5707963267948966 0 0" xyz="0 0 0"/>
      <inertia ixx="0.008" ixy="0" ixz="0" iyy="0.008" iyz="0" izz="0.015"/>
    </inertial>
    <visual>
      <origin rpy="1.5707963267948966 0 0" xyz="0 0 0"/>
      <geometry>
        <cylinder length="0.12" radius="0.22"/>
      </geometry>
      <material name="Black"/>
    </visual>
    <collision>
      <origin rpy="1.5707963267948966 0 0" xyz="0 0 0"/>
      <geometry>
        <cylinder length="0.12" radius="0.22"/>
      </geometry>
    </collision>
  </link>

  <!-- Joint : Front Left wheel and Chassis -->  
  <joint name="front_left_joint" type="continuous">
    <parent link="chassis"/>
    <child link="front_left_wheel"/>
    <origin rpy="0 0 0" xyz="0.4533333333333333 0.46 -0.15"/>
    <axis xyz="0 1 0"/>
    <dynamics damping="0.2" friction="1.0"/>
    <limit effort="100" velocity="1.0"/>
  </joint>

  <!-- Front Right Wheel -->
  <link name="front_right_wheel">
    <inertial>
      <mass value="0.7"/> 
      <origin rpy="1.5707963267948966 0 0" xyz="0 0 0"/>
      <inertia ixx="0.008" ixy="0" ixz="0" iyy="0.008" iyz="0" izz="0.015"/> 
    </inertial>
    <visual>
      <origin rpy="1.5707963267948966 0 0" xyz="0 0 0"/>
      <geometry>
        <cylinder length="0.12" radius="0.22"/>
      </geometry>
      <material name="Black"/>
    </visual>
    <collision>
      <origin rpy="1.5707963267948966 0 0" xyz="0 0 0"/>
      <geometry>
        <cylinder length="0.12" radius="0.22"/>
      </geometry>
    </collision>
  </link>

  <!-- Joint: Front Right Wheel and Chassis -->
  <joint name="front_right_joint" type="continuous">
    <parent link="chassis"/>
    <child link="front_right_wheel"/>
    <origin rpy="0 0 0" xyz="0.4533333333333333 -0.46 -0.15"/>
    <axis xyz="0 1 0"/>
    <dynamics damping="0.2" friction="1.0"/>
    <limit effort="100" velocity="1.0"/>    
  </joint>


  <!-- REAR WHEELS -->
  <!-- Rear Left Wheel -->
  <link name="rear_left_wheel">
    <inertial>
      <mass value="0.233"/> <!-- changed to low mass for gazebo -->
      <origin rpy="1.5707963267948966 0 0" xyz="0 0 0"/>
      <inertia ixx="0.003099" ixy="0" ixz="0" iyy="0.0003099" iyz="0" izz="0.0056386"/> <!-- recalculated --> 
    </inertial>
    <visual>
      <origin rpy="1.5707963267948966 0 0" xyz="0 0 0"/>
      <geometry>
        <cylinder length="0.12" radius="0.22"/>
      </geometry>
      <material name="Black"/>
    </visual>
    <collision>
      <origin rpy="1.5707963267948966 0 0" xyz="0 0 0"/>
      <geometry>
        <cylinder length="0.12" radius="0.22"/>
      </geometry>
    </collision>
  </link>

  <!-- Joint: Rear Left Wheel and Chassis -->
  <joint name="rear_left_joint" type="revolute"> <!-- changed from continuous to fixed -->
    <mimic joint="front_left_joint" multiplier="1" offset="0"/>
    <parent link="chassis"/>
    <child link="rear_left_wheel"/>
    <origin rpy="0 0 0" xyz="-0.4533333333333333 0.46 -0.15"/>
    <axis xyz="0 1 0"/>
    <dynamics damping="0.2" friction="1.0"/> <!-- added this for gazebo -->
    <!--limit effort="100" velocity="1.0"/-->
    <limit lower="0.0" upper="0.0" effort="100" velocity="1.0"/> <!-- for revolute -->  
  </joint>

  <!-- Rear Right Wheel -->
  <link name="rear_right_wheel">
    <inertial>
      <mass value="0.233"/> 
      <origin rpy="1.5707963267948966 0 0" xyz="0 0 0"/>
      <inertia ixx="0.003099" ixy="0" ixz="0" iyy="0.0003099" iyz="0" izz="0.0056386"/>
    </inertial>
    <visual>
      <origin rpy="1.5707963267948966 0 0" xyz="0 0 0"/>
      <geometry>
        <cylinder length="0.12" radius="0.22"/>
      </geometry>
      <material name="Black"/>
    </visual>
    <collision>
      <origin rpy="1.5707963267948966 0 0" xyz="0 0 0"/>
      <geometry>
        <cylinder length="0.12" radius="0.22"/>
      </geometry>
    </collision>
  </link>

  <!-- Joint: Rear Right Wheel and Chassis -->
  <joint name="rear_right_joint" type="revolute">
    <mimic joint="front_right_joint" multiplier="1" offset="0"/>    
    <parent link="chassis"/>
    <child link="rear_right_wheel"/>
    <origin rpy="0 0 0" xyz="-0.4533333333333333 -0.46 -0.15"/>
    <axis xyz="0 1 0"/>
    <dynamics damping="0.2" friction="1.0"/>
    <!--limit effort="100" velocity="1.0"/-->
    <limit lower="0.0" upper="0.0" effort="100" velocity="1.0"/> <!-- for revolute-->  
  </joint>


  <!-- LIDAR -->
  <!-- Lidar Link -->  
  <link name="lidar">
    <inertial>
      <mass value="0.114"/>
      <origin rpy="0 0 0" xyz="0 0 0"/>
      <inertia ixx="0.0003458" ixy="0" ixz="0" iyy="0.0003458" iyz="0" izz="0.0003458"/>
    </inertial>
    <visual>
      <origin rpy="0 0 0" xyz="0 0 0"/>
      <geometry>
        <cylinder length="0.08" radius="0.1"/>
      </geometry>
      <material name="Red"/>
    </visual>
    <collision>
      <origin rpy="0 0 0" xyz="0 0 0"/>
      <geometry>
        <cylinder length="0.08" radius="0.1"/>
      </geometry>
    </collision>
  </link>

  <!-- Joint: Lidar to Chassis -->
  <joint name="lidar_joint" type="fixed">
    <parent link="chassis"/>
    <child link="lidar"/>
    <origin rpy="0 0 0" xyz="0 0 0.19"/>
  </joint>


  <!-- Camera Frame -->
  <link name="camera">
    <inertial>
      <mass value="0.1"/>
      <origin rpy="0 0 0" xyz="0 0 0"/>
      <inertia ixx="0.0003866666666666667" ixy="0" ixz="0" iyy="0.00010666666666666668" iyz="0" izz="0.0003866666666666667"/>
    </inertial>
    <visual>
      <origin rpy="0 0 0" xyz="0 0 0"/>
      <geometry>
        <box size="0.08 0.2 0.08"/>
      </geometry>
      <material name="Blue"/>
    </visual>
    <collision>
      <origin rpy="0 0 0" xyz="0 0 0"/>
      <geometry>
        <box size="0.08 0.2 0.08"/>
      </geometry>
    </collision>
  </link>

  <!-- Joint: Camera to Chassis -->
  <joint name="camera_joint" type="fixed">
    <parent link="chassis"/>
    <child link="camera"/>
    <origin rpy="0 0 0" xyz="0.64 0 0"/>
  </joint>

  <!-- Camera Optical Frame -->
  <link name="camera_optical"/>
  <joint name="camera_optical_joint" type="fixed">
    <parent link="camera"/>
    <child link="camera_optical"/>
    <!-- Rotate to align with ROS optical frame convention:
           X: Right, Y: Down, Z: Forward -->
    <origin rpy="-1.5707963267948966 0 -1.5707963267948966" xyz="0 0 0"/>
  </joint>


  <gazebo>
    <plugin name="skid_steer_controller" filename="libgazebo_ros_diff_drive.so">
        <left_joint>front_left_joint</left_joint>
        <right_joint>front_right_joint</right_joint>
        <wheel_separation>0.92</wheel_separation>
        <wheel_diameter>0.44</wheel_diameter>

        <max_wheel_torque>200</max_wheel_torque>
        <max_wheel_acceleration>10.0</max_wheel_acceleration>

        <odometry_frame>odom</odometry_frame>
        <robot_base_frame>base_link</robot_base_frame>

        <publish_odom>true</publish_odom>
        <publish_odom_tf>true</publish_odom_tf>
        <publish_wheel_tf>true</publish_wheel_tf>
    </plugin>
  </gazebo>


  <gazebo reference="lidar">
    <sensor type="ray" name="lidar_sensor">
      <pose>0 0 0 0 0 0</pose>
      <visualize>true</visualize>
      <update_rate>10</update_rate>
      <ray>
        <scan>
          <horizontal>
            <samples>720</samples>
            <min_angle>-3.14</min_angle>
            <max_angle>3.14</max_angle>
          </horizontal>
        </scan>
        <range>
          <min>0.1</min>
          <max>12</max>
        </range>
      </ray>
      <plugin name="lidar_plugin" filename="libgazebo_ros_ray_sensor.so">
        <ros>
          <namespace>/</namespace>
          <remapping>~/out:=scan</remapping>
        </ros>
        <output_type>sensor_msgs/LaserScan</output_type>
        <frame_name>lidar</frame_name>
      </plugin>
    </sensor>
  </gazebo>


<!--gazebo>
    <plugin name="diff_robot_joint_state" filename="libgazebo_ros_joint_state_publisher.so">
        <ros>
          <remapping>~/out:=joint_states</remapping>
        </ros>
        <update_rate>30</update_rate>
        <joint_name>front_left_joint</joint_name>
        <joint_name>front_right_joint</joint_name>
      </plugin>
</gazebo-->

  <gazebo reference="camera">
    <sensor type="camera" name="camera_sensor">
      <pose>0 0 0 0 0 0</pose>
      <visualize>false</visualize>
      <update_rate>30</update_rate>
      <camera>
        <horizontal_fov>1.0472</horizontal_fov>
        <image>
          <width>640</width>
          <height>480</height>
        </image>
        <clip>
          <near>0.1</near>
          <far>100</far>
        </clip>
      </camera>
      <plugin name="camera_plugin" filename="libgazebo_ros_camera.so">
        <ros>
          <namespace>/</namespace>
          <remapping>~/image_raw:=camera/image_raw</remapping>
        </ros>
        <camera_name>camera</camera_name>
        <frame_name>camera_optical</frame_name> 
      </plugin>
    </sensor>
  </gazebo>  


<gazebo reference="front_left_wheel">
  <material>Gazebo/Black</material>
</gazebo>

<gazebo reference="front_right_wheel">
  <material>Gazebo/Black</material>
</gazebo>

<gazebo reference="rear_right_wheel">
  <material>Gazebo/Black</material>
</gazebo>

<gazebo reference="rear_left_wheel">
  <material>Gazebo/Black</material>
</gazebo>

<gazebo reference="lidar">
  <material>Gazebo/Blue</material>
</gazebo>

<gazebo reference="camera">
  <material>Gazebo/Red</material>
</gazebo>

<gazebo reference="chassis">
  <material>Gazebo/DarkGray</material>
</gazebo>

</robot>